<sdf version='1.7'>
  <model name='weed'>
    <link name='base_footprint'>
      <inertial>
        <pose>-0 0 0.826316 0 -0 0</pose>
        <mass>38</mass>
        <inertia>
          <ixx>2.75868</ixx>
          <ixy>0</ixy>
          <ixz>-1.46082e-18</ixz>
          <iyy>1.18368</iyy>
          <iyz>0</iyz>
          <izz>3.495</izz>
        </inertia>
      </inertial>
      <collision name='base_footprint_fixed_joint_lump__back_left_collision'>
        <pose>-0.4 0.65 0.8 0 -0 0</pose>
        <geometry>
          <box>
            <size>0.05 0.05 0.4</size>
          </box>
        </geometry>
        <surface>
          <contact>
            <ode/>
          </contact>
          <friction>
            <ode/>
          </friction>
        </surface>
      </collision>
      <collision name='base_footprint_fixed_joint_lump__back_right_collision_1'>
        <pose>-0.4 -0.65 0.8 0 -0 0</pose>
        <geometry>
          <box>
            <size>0.05 0.05 0.4</size>
          </box>
        </geometry>
        <surface>
          <contact>
            <ode/>
          </contact>
          <friction>
            <ode/>
          </friction>
        </surface>
      </collision>
      <collision name='base_footprint_fixed_joint_lump__front_left_collision_2'>
        <pose>0.4 0.65 0.8 0 -0 0</pose>
        <geometry>
          <box>
            <size>0.05 0.05 0.5</size>
          </box>
        </geometry>
        <surface>
          <contact>
            <ode/>
          </contact>
          <friction>
            <ode/>
          </friction>
        </surface>
      </collision>
      <collision name='base_footprint_fixed_joint_lump__front_right_collision_3'>
        <pose>0.4 -0.65 0.8 0 -0 0</pose>
        <geometry>
          <box>
            <size>0.05 0.05 0.5</size>
          </box>
        </geometry>
        <surface>
          <contact>
            <ode/>
          </contact>
          <friction>
            <ode/>
          </friction>
        </surface>
      </collision>
      <collision name='base_footprint_fixed_joint_lump__top_back_collision_4'>
        <pose>-0.4 0 1.05 0 -0 0</pose>
        <geometry>
          <box>
            <size>0.05 1.3 0.05</size>
          </box>
        </geometry>
        <surface>
          <contact>
            <ode/>
          </contact>
          <friction>
            <ode/>
          </friction>
        </surface>
      </collision>
      <collision name='base_footprint_fixed_joint_lump__top_front_collision_5'>
        <pose>0.4 0 1.05 0 -0 0</pose>
        <geometry>
          <box>
            <size>0.05 1.3 0.05</size>
          </box>
        </geometry>
        <surface>
          <contact>
            <ode/>
          </contact>
          <friction>
            <ode/>
          </friction>
        </surface>
      </collision>
      <collision name='base_footprint_fixed_joint_lump__top_left_collision_6'>
        <pose>0 0.65 1.05 0 -0 0</pose>
        <geometry>
          <box>
            <size>0.8 0.05 0.05</size>
          </box>
        </geometry>
        <surface>
          <contact>
            <ode/>
          </contact>
          <friction>
            <ode/>
          </friction>
        </surface>
      </collision>
      <collision name='base_footprint_fixed_joint_lump__top_right_collision_7'>
        <pose>0 -0.65 1.05 0 -0 0</pose>
        <geometry>
          <box>
            <size>0.8 0.05 0.05</size>
          </box>
        </geometry>
        <surface>
          <contact>
            <ode/>
          </contact>
          <friction>
            <ode/>
          </friction>
        </surface>
      </collision>
      <visual name='base_footprint_fixed_joint_lump__back_left_visual'>
        <pose>-0.4 0.65 0.8 0 -0 0</pose>
        <geometry>
          <box>
            <size>0.05 0.05 0.5</size>
          </box>
        </geometry>
        <material>
          <script>
            <name>Gazebo/Red</name>
            <uri>file://media/materials/scripts/gazebo.material</uri>
          </script>
        </material>
      </visual>
      <visual name='base_footprint_fixed_joint_lump__back_right_visual_1'>
        <pose>-0.4 -0.65 0.8 0 -0 0</pose>
        <geometry>
          <box>
            <size>0.05 0.05 0.5</size>
          </box>
        </geometry>
        <material>
          <script>
            <name>Gazebo/Red</name>
            <uri>file://media/materials/scripts/gazebo.material</uri>
          </script>
        </material>
      </visual>
      <visual name='base_footprint_fixed_joint_lump__front_left_visual_2'>
        <pose>0.4 0.65 0.8 0 -0 0</pose>
        <geometry>
          <box>
            <size>0.05 0.05 0.5</size>
          </box>
        </geometry>
        <material>
          <script>
            <name>Gazebo/Red</name>
            <uri>file://media/materials/scripts/gazebo.material</uri>
          </script>
        </material>
      </visual>
      <visual name='base_footprint_fixed_joint_lump__front_right_visual_3'>
        <pose>0.4 -0.65 0.8 0 -0 0</pose>
        <geometry>
          <box>
            <size>0.05 0.05 0.5</size>
          </box>
        </geometry>
        <material>
          <script>
            <name>Gazebo/Red</name>
            <uri>file://media/materials/scripts/gazebo.material</uri>
          </script>
        </material>
      </visual>
      <visual name='base_footprint_fixed_joint_lump__top_back_visual_4'>
        <pose>-0.4 0 1.05 0 -0 0</pose>
        <geometry>
          <box>
            <size>0.05 1.3 0.05</size>
          </box>
        </geometry>
        <material>
          <script>
            <name>Gazebo/Red</name>
            <uri>file://media/materials/scripts/gazebo.material</uri>
          </script>
        </material>
      </visual>
      <visual name='base_footprint_fixed_joint_lump__top_front_visual_5'>
        <pose>0.4 0 1.05 0 -0 0</pose>
        <geometry>
          <box>
            <size>0.05 1.3 0.05</size>
          </box>
        </geometry>
        <material>
          <script>
            <name>Gazebo/Red</name>
            <uri>file://media/materials/scripts/gazebo.material</uri>
          </script>
        </material>
      </visual>
      <visual name='base_footprint_fixed_joint_lump__top_left_visual_6'>
        <pose>0 0.65 1.05 0 -0 0</pose>
        <geometry>
          <box>
            <size>0.8 0.05 0.05</size>
          </box>
        </geometry>
        <material>
          <script>
            <name>Gazebo/Red</name>
            <uri>file://media/materials/scripts/gazebo.material</uri>
          </script>
        </material>
      </visual>
      <visual name='base_footprint_fixed_joint_lump__top_right_visual_7'>
        <pose>0 -0.65 1.05 0 -0 0</pose>
        <geometry>
          <box>
            <size>0.8 0.05 0.05</size>
          </box>
        </geometry>
        <material>
          <script>
            <name>Gazebo/Red</name>
            <uri>file://media/materials/scripts/gazebo.material</uri>
          </script>
        </material>
      </visual>
    </link>
    <joint name='back_cl_j' type='revolute'>
      <pose relative_to='base_footprint'>-0.4 0.65 0.18 0 -0 0</pose>
      <parent>base_footprint</parent>
      <child>back_c_l</child>
      <axis>
        <xyz>0 0 1</xyz>
        <limit>
          <effort>10000</effort>
          <velocity>1000</velocity>
          <lower>-1e+16</lower>
          <upper>1e+16</upper>
        </limit>
        <dynamics>
          <spring_reference>0</spring_reference>
          <spring_stiffness>0</spring_stiffness>
        </dynamics>
      </axis>
    </joint>
    <link name='back_c_l'>
      <pose relative_to='back_cl_j'>0 0 0 0 -0 0</pose>
      <inertial>
        <pose>0.040802 -2e-06 -0.075306 0 -0 0</pose>
        <mass>3</mass>
        <inertia>
          <ixx>0.011943</ixx>
          <ixy>1.51346e-07</ixy>
          <ixz>0.00470867</ixz>
          <iyy>0.0127196</iyy>
          <iyz>-3.20566e-07</iyz>
          <izz>0.00449043</izz>
        </inertia>
      </inertial>
      <collision name='back_c_l_collision'>
        <pose>0 0 0 0 -0 0</pose>
        <geometry>
          <box>
            <size>0.01 0.01 0.01</size>
          </box>
        </geometry>
      </collision>
      <visual name='back_c_l_visual'>
        <pose>0 0 0 0 -0 0</pose>
        <geometry>
          <box>
            <size>0.01 0.01 0.01</size>
          </box>
        </geometry>
      </visual>
    </link>
    <joint name='back_wl_j' type='revolute'>
      <pose relative_to='back_c_l'>0.079407 0 0 1.57 -0 0</pose>
      <parent>back_c_l</parent>
      <child>back_w_l</child>
      <axis>
        <xyz>0 0 1</xyz>
        <limit>
          <lower>-1e+16</lower>
          <upper>1e+16</upper>
        </limit>
        <dynamics>
          <spring_reference>0</spring_reference>
          <spring_stiffness>0</spring_stiffness>
        </dynamics>
      </axis>
    </joint>
    <link name='back_w_l'>
      <pose relative_to='back_wl_j'>0 0 0 0 -0 0</pose>
      <inertial>
        <pose>-0.000406 -6.8e-05 1.5e-05 0 -0 0</pose>
        <mass>0.630033</mass>
        <inertia>
          <ixx>0.00669221</ixx>
          <ixy>1.46876e-06</ixy>
          <ixz>-1.83677e-07</ixz>
          <iyy>0.00381017</iyy>
          <iyz>2.02229e-07</iyz>
          <izz>0.00380711</izz>
        </inertia>
      </inertial>
      <collision name='back_w_l_collision'>
        <pose>0 0 0 0 -0 0</pose>
        <geometry>
          <cylinder>
            <length>0.078</length>
            <radius>0.13</radius>
          </cylinder>
        </geometry>
        <surface>
          <contact>
            <ode/>
          </contact>
          <friction>
            <ode/>
          </friction>
        </surface>
      </collision>
      <visual name='back_w_l_visual'>
        <pose>0 0 0 0 -0 0</pose>
        <geometry>
          <cylinder>
            <length>0.078</length>
            <radius>0.13</radius>
          </cylinder>
        </geometry>
        <material>
          <script>
            <name>Gazebo/Black</name>
            <uri>file://media/materials/scripts/gazebo.material</uri>
          </script>
        </material>
      </visual>
    </link>
    <joint name='back_cr_j' type='revolute'>
      <pose relative_to='base_footprint'>-0.4 -0.65 0.18 0 -0 0</pose>
      <parent>base_footprint</parent>
      <child>back_c_r</child>
      <axis>
        <xyz>0 0 1</xyz>
        <limit>
          <effort>10000</effort>
          <velocity>1000</velocity>
          <lower>-1e+16</lower>
          <upper>1e+16</upper>
        </limit>
        <dynamics>
          <spring_reference>0</spring_reference>
          <spring_stiffness>0</spring_stiffness>
        </dynamics>
      </axis>
    </joint>
    <link name='back_c_r'>
      <pose relative_to='back_cr_j'>0 0 0 0 -0 0</pose>
      <inertial>
        <pose>-0.040802 2e-06 -0.075306 0 -0 0</pose>
        <mass>3</mass>
        <inertia>
          <ixx>0.011943</ixx>
          <ixy>1.51329e-07</ixy>
          <ixz>-0.00470867</ixz>
          <iyy>0.0127196</iyy>
          <iyz>3.20627e-07</iyz>
          <izz>0.00449043</izz>
        </inertia>
      </inertial>
      <collision name='back_c_r_collision'>
        <pose>0 0 0 0 -0 0</pose>
        <geometry>
          <box>
            <size>0.01 0.01 0.01</size>
          </box>
        </geometry>
      </collision>
      <visual name='back_c_r_visual'>
        <pose>0 0 0 0 -0 0</pose>
        <geometry>
          <box>
            <size>0.01 0.01 0.01</size>
          </box>
        </geometry>
      </visual>
    </link>
    <joint name='back_wr_j' type='revolute'>
      <pose relative_to='back_c_r'>-0.079407 0 0 1.57 -0 0</pose>
      <parent>back_c_r</parent>
      <child>back_w_r</child>
      <axis>
        <xyz>0 0 1</xyz>
        <limit>
          <lower>-1e+16</lower>
          <upper>1e+16</upper>
        </limit>
        <dynamics>
          <spring_reference>0</spring_reference>
          <spring_stiffness>0</spring_stiffness>
        </dynamics>
      </axis>
    </joint>
    <link name='back_w_r'>
      <pose relative_to='back_wr_j'>0 0 0 0 -0 0</pose>
      <inertial>
        <pose>-0.000406 -6.8e-05 1.5e-05 0 -0 0</pose>
        <mass>0.630033</mass>
        <inertia>
          <ixx>0.00669221</ixx>
          <ixy>1.46876e-06</ixy>
          <ixz>-1.83677e-07</ixz>
          <iyy>0.00381017</iyy>
          <iyz>2.02229e-07</iyz>
          <izz>0.00380711</izz>
        </inertia>
      </inertial>
      <collision name='back_w_r_collision'>
        <pose>0 0 0 0 -0 0</pose>
        <geometry>
          <cylinder>
            <length>0.078</length>
            <radius>0.13</radius>
          </cylinder>
        </geometry>
        <surface>
          <contact>
            <ode/>
          </contact>
          <friction>
            <ode/>
          </friction>
        </surface>
      </collision>
      <visual name='back_w_r_visual'>
        <pose>0 0 0 0 -0 0</pose>
        <geometry>
          <cylinder>
            <length>0.078</length>
            <radius>0.13</radius>
          </cylinder>
        </geometry>
        <material>
          <script>
            <name>Gazebo/Black</name>
            <uri>file://media/materials/scripts/gazebo.material</uri>
          </script>
        </material>
      </visual>
    </link>
    <joint name='front_wl_j' type='revolute'>
      <pose relative_to='base_footprint'>0.4 0.65 0.26 1.57 -0 0</pose>
      <parent>base_footprint</parent>
      <child>front_w_l</child>
      <axis>
        <xyz>0 0 1</xyz>
        <limit>
          <lower>-1e+16</lower>
          <upper>1e+16</upper>
        </limit>
        <dynamics>
          <spring_reference>0</spring_reference>
          <spring_stiffness>0</spring_stiffness>
        </dynamics>
      </axis>
    </joint>
    <link name='front_w_l'>
      <pose relative_to='front_wl_j'>0 0 0 0 -0 0</pose>
      <inertial>
        <pose>0 0 0 0 -0 0</pose>
        <mass>3.63003</mass>
        <inertia>
          <ixx>0.00669221</ixx>
          <ixy>1.46876e-06</ixy>
          <ixz>-1.83677e-07</ixz>
          <iyy>0.00381017</iyy>
          <iyz>2.02229e-07</iyz>
          <izz>0.00380711</izz>
        </inertia>
      </inertial>
      <collision name='front_w_l_collision'>
        <pose>0 0 0 0 -0 0</pose>
        <geometry>
          <cylinder>
            <length>0.105</length>
            <radius>0.21</radius>
          </cylinder>
        </geometry>
        <surface>
          <contact>
            <ode/>
          </contact>
          <friction>
            <ode/>
          </friction>
        </surface>
      </collision>
      <visual name='front_w_l_visual'>
        <pose>0 0 0 0 -0 0</pose>
        <geometry>
          <cylinder>
            <length>0.105</length>
            <radius>0.21</radius>
          </cylinder>
        </geometry>
        <material>
          <script>
            <name>Gazebo/Black</name>
            <uri>file://media/materials/scripts/gazebo.material</uri>
          </script>
        </material>
      </visual>
    </link>
    <joint name='front_wr_j' type='revolute'>
      <pose relative_to='base_footprint'>0.4 -0.65 0.26 1.57 -0 0</pose>
      <parent>base_footprint</parent>
      <child>front_w_r</child>
      <axis>
        <xyz>0 0 1</xyz>
        <limit>
          <lower>-1e+16</lower>
          <upper>1e+16</upper>
        </limit>
        <dynamics>
          <spring_reference>0</spring_reference>
          <spring_stiffness>0</spring_stiffness>
        </dynamics>
      </axis>
    </joint>
    <link name='front_w_r'>
      <pose relative_to='front_wr_j'>0 0 0 0 -0 0</pose>
      <inertial>
        <pose>0 0 0 0 -0 0</pose>
        <mass>3.63003</mass>
        <inertia>
          <ixx>0.00669221</ixx>
          <ixy>1.46876e-06</ixy>
          <ixz>-1.83677e-07</ixz>
          <iyy>0.00381017</iyy>
          <iyz>2.02229e-07</iyz>
          <izz>0.00380711</izz>
        </inertia>
      </inertial>
      <collision name='front_w_r_collision'>
        <pose>0 0 0 0 -0 0</pose>
        <geometry>
          <cylinder>
            <length>0.105</length>
            <radius>0.21</radius>
          </cylinder>
        </geometry>
        <surface>
          <contact>
            <ode/>
          </contact>
          <friction>
            <ode/>
          </friction>
        </surface>
      </collision>
      <visual name='front_w_r_visual'>
        <pose>0 0 0 0 -0 0</pose>
        <geometry>
          <cylinder>
            <length>0.105</length>
            <radius>0.21</radius>
          </cylinder>
        </geometry>
        <material>
          <script>
            <name>Gazebo/Black</name>
            <uri>file://media/materials/scripts/gazebo.material</uri>
          </script>
        </material>
      </visual>
    </link>
    <static>0</static>
    <plugin name='diff_drive' filename='libgazebo_ros_diff_drive.so'>
      <update_rate>30</update_rate>
      <left_joint>front_wl_j</left_joint>
      <right_joint>front_wr_j</right_joint>
      <wheel_separation>1.4</wheel_separation>
      <wheel_diameter>0.42</wheel_diameter>
      <max_wheel_torque>20</max_wheel_torque>
      <max_wheel_acceleration>1.0</max_wheel_acceleration>
      <command_topic>cmd_vel</command_topic>
      <publish_odom>1</publish_odom>
      <publish_odom_tf>1</publish_odom_tf>
      <publish_wheel_tf>0</publish_wheel_tf>
      <odometry_topic>odom</odometry_topic>
      <odometry_frame>odom</odometry_frame>
      <robot_base_frame>base_footprint</robot_base_frame>
    </plugin>
    <plugin name='turtlebot3_joint_state' filename='libgazebo_ros_joint_state_publisher.so'>
      <ros>
        <remapping>~/out:=joint_states</remapping>
      </ros>
      <update_rate>30</update_rate>
      <joint_name>front_wl_j</joint_name>
      <joint_name>front_wr_j</joint_name>
      <joint_name>back_wl_j</joint_name>
      <joint_name>back_wr_j</joint_name>
      <joint_name>back_cl_j</joint_name>
      <joint_name>back_cr_j</joint_name>
    </plugin>
  </model>
</sdf>
