<sdf version='1.7'>
  <model name='weed'>
    <link name='base_footprint'>
      <inertial>
        <pose>0.002925 0.000256 0.82392 0 -0 0</pose>
        <mass>38.564</mass>
        <inertia>
          <ixx>2.77765</ixx>
          <ixy>-0.00194513</ixy>
          <ixz>0.0182082</ixz>
          <iyy>1.22133</iyy>
          <iyz>0.00159322</iyz>
          <izz>3.52128</izz>
        </inertia>
      </inertial>
      <collision name='base_footprint_fixed_joint_lump__back_left_collision'>
        <pose>-0.4 0.65 0.8 0 -0 0</pose>
        <geometry>
          <box>
            <size>0.05 0.05 0.4</size>
          </box>
        </geometry>
        <surface>
          <contact>
            <ode/>
          </contact>
          <friction>
            <ode/>
          </friction>
        </surface>
      </collision>
      <collision name='base_footprint_fixed_joint_lump__back_right_collision_1'>
        <pose>-0.4 -0.65 0.8 0 -0 0</pose>
        <geometry>
          <box>
            <size>0.05 0.05 0.4</size>
          </box>
        </geometry>
        <surface>
          <contact>
            <ode/>
          </contact>
          <friction>
            <ode/>
          </friction>
        </surface>
      </collision>
      <collision name='base_footprint_fixed_joint_lump__camera_link_collision_2'>
        <pose>0.4 0 0.55 0 -0 0</pose>
        <geometry>
          <box>
            <size>0.015 0.03 0.027</size>
          </box>
        </geometry>
        <surface>
          <contact>
            <ode/>
          </contact>
          <friction>
            <ode/>
          </friction>
        </surface>
      </collision>
      <collision name='base_footprint_fixed_joint_lump__front_left_collision_3'>
        <pose>0.4 0.65 0.8 0 -0 0</pose>
        <geometry>
          <box>
            <size>0.05 0.05 0.5</size>
          </box>
        </geometry>
        <surface>
          <contact>
            <ode/>
          </contact>
          <friction>
            <ode/>
          </friction>
        </surface>
      </collision>
      <collision name='base_footprint_fixed_joint_lump__front_right_collision_4'>
        <pose>0.4 -0.65 0.8 0 -0 0</pose>
        <geometry>
          <box>
            <size>0.05 0.05 0.5</size>
          </box>
        </geometry>
        <surface>
          <contact>
            <ode/>
          </contact>
          <friction>
            <ode/>
          </friction>
        </surface>
      </collision>
      <collision name='base_footprint_fixed_joint_lump__realsense_camera_link_collision_5'>
        <pose>0.2 0 0.6625 0 -0 0</pose>
        <geometry>
          <box>
            <size>0.02505 0.09 0.025</size>
          </box>
        </geometry>
        <surface>
          <contact>
            <ode/>
          </contact>
          <friction>
            <ode/>
          </friction>
        </surface>
      </collision>
      <collision name='base_footprint_fixed_joint_lump__top_back_collision_6'>
        <pose>-0.4 0 1.05 0 -0 0</pose>
        <geometry>
          <box>
            <size>0.05 1.3 0.05</size>
          </box>
        </geometry>
        <surface>
          <contact>
            <ode/>
          </contact>
          <friction>
            <ode/>
          </friction>
        </surface>
      </collision>
      <collision name='base_footprint_fixed_joint_lump__top_front_collision_7'>
        <pose>0.4 0 1.05 0 -0 0</pose>
        <geometry>
          <box>
            <size>0.05 1.3 0.05</size>
          </box>
        </geometry>
        <surface>
          <contact>
            <ode/>
          </contact>
          <friction>
            <ode/>
          </friction>
        </surface>
      </collision>
      <collision name='base_footprint_fixed_joint_lump__top_left_collision_8'>
        <pose>0 0.65 1.05 0 -0 0</pose>
        <geometry>
          <box>
            <size>0.8 0.05 0.05</size>
          </box>
        </geometry>
        <surface>
          <contact>
            <ode/>
          </contact>
          <friction>
            <ode/>
          </friction>
        </surface>
      </collision>
      <collision name='base_footprint_fixed_joint_lump__top_right_collision_9'>
        <pose>0 -0.65 1.05 0 -0 0</pose>
        <geometry>
          <box>
            <size>0.8 0.05 0.05</size>
          </box>
        </geometry>
        <surface>
          <contact>
            <ode/>
          </contact>
          <friction>
            <ode/>
          </friction>
        </surface>
      </collision>
      <visual name='base_footprint_fixed_joint_lump__back_left_visual'>
        <pose>-0.4 0.65 0.8 0 -0 0</pose>
        <geometry>
          <box>
            <size>0.05 0.05 0.5</size>
          </box>
        </geometry>
        <material>
          <script>
            <name>Gazebo/Red</name>
            <uri>file://media/materials/scripts/gazebo.material</uri>
          </script>
        </material>
      </visual>
      <visual name='base_footprint_fixed_joint_lump__back_right_visual_1'>
        <pose>-0.4 -0.65 0.8 0 -0 0</pose>
        <geometry>
          <box>
            <size>0.05 0.05 0.5</size>
          </box>
        </geometry>
        <material>
          <script>
            <name>Gazebo/Red</name>
            <uri>file://media/materials/scripts/gazebo.material</uri>
          </script>
        </material>
      </visual>
      <visual name='base_footprint_fixed_joint_lump__camera_link_visual_2'>
        <pose>0.4 0 0.55 0 -0 0</pose>
        <geometry>
          <box>
            <size>0.015 0.03 0.027</size>
          </box>
        </geometry>
      </visual>
      <visual name='base_footprint_fixed_joint_lump__front_left_visual_3'>
        <pose>0.4 0.65 0.8 0 -0 0</pose>
        <geometry>
          <box>
            <size>0.05 0.05 0.5</size>
          </box>
        </geometry>
        <material>
          <script>
            <name>Gazebo/Red</name>
            <uri>file://media/materials/scripts/gazebo.material</uri>
          </script>
        </material>
      </visual>
      <visual name='base_footprint_fixed_joint_lump__front_right_visual_4'>
        <pose>0.4 -0.65 0.8 0 -0 0</pose>
        <geometry>
          <box>
            <size>0.05 0.05 0.5</size>
          </box>
        </geometry>
        <material>
          <script>
            <name>Gazebo/Red</name>
            <uri>file://media/materials/scripts/gazebo.material</uri>
          </script>
        </material>
      </visual>
      <visual name='base_footprint_fixed_joint_lump__realsense_camera_link_visual_5'>
        <pose>0.2149 0 0.6625 1.5708 -0 1.5708</pose>
        <geometry>
          <box>
            <size>0.1 0.1 0.1</size>
          </box>
        </geometry>
      </visual>
      <visual name='base_footprint_fixed_joint_lump__top_back_visual_6'>
        <pose>-0.4 0 1.05 0 -0 0</pose>
        <geometry>
          <box>
            <size>0.05 1.3 0.05</size>
          </box>
        </geometry>
        <material>
          <script>
            <name>Gazebo/Red</name>
            <uri>file://media/materials/scripts/gazebo.material</uri>
          </script>
        </material>
      </visual>
      <visual name='base_footprint_fixed_joint_lump__top_front_visual_7'>
        <pose>0.4 0 1.05 0 -0 0</pose>
        <geometry>
          <box>
            <size>0.05 1.3 0.05</size>
          </box>
        </geometry>
        <material>
          <script>
            <name>Gazebo/Red</name>
            <uri>file://media/materials/scripts/gazebo.material</uri>
          </script>
        </material>
      </visual>
      <visual name='base_footprint_fixed_joint_lump__top_left_visual_8'>
        <pose>0 0.65 1.05 0 -0 0</pose>
        <geometry>
          <box>
            <size>0.8 0.05 0.05</size>
          </box>
        </geometry>
        <material>
          <script>
            <name>Gazebo/Red</name>
            <uri>file://media/materials/scripts/gazebo.material</uri>
          </script>
        </material>
      </visual>
      <visual name='base_footprint_fixed_joint_lump__top_right_visual_9'>
        <pose>0 -0.65 1.05 0 -0 0</pose>
        <geometry>
          <box>
            <size>0.8 0.05 0.05</size>
          </box>
        </geometry>
        <material>
          <script>
            <name>Gazebo/Red</name>
            <uri>file://media/materials/scripts/gazebo.material</uri>
          </script>
        </material>
      </visual>
      <sensor name='camera' type='camera'>
        <update_rate>30</update_rate>
        <camera name='head'>
          <horizontal_fov>1.39626</horizontal_fov>
          <image>
            <width>800</width>
            <height>600</height>
            <format>R8G8B8</format>
          </image>
          <clip>
            <near>0.02</near>
            <far>300</far>
          </clip>
          <noise>
            <type>gaussian</type>
            <mean>0</mean>
            <stddev>0.007</stddev>
          </noise>
        </camera>
        <plugin name='camera_controller' filename='libgazebo_ros_camera.so'>
          <alwaysOn>1</alwaysOn>
          <updateRate>30.0</updateRate>
          <cameraName>iRobot/camera</cameraName>
          <imageTopicName>image_raw</imageTopicName>
          <cameraInfoTopicName>camera_info</cameraInfoTopicName>
          <frameName>camera_link</frameName>
          <hackBaseline>0.07</hackBaseline>
          <distortionK1>0.0</distortionK1>
          <distortionK2>0.0</distortionK2>
          <distortionK3>0.0</distortionK3>
          <distortionT1>0.0</distortionT1>
          <distortionT2>0.0</distortionT2>
        </plugin>
        <pose>0.4 0 0.55 0 -0 0</pose>
      </sensor>
      <sensor name='realsense_camera' type='camera'>
        <update_rate>30</update_rate>
        <visualize>1</visualize>
        <camera name='head'>
          <horizontal_fov>1.39626</horizontal_fov>
          <image>
            <width>800</width>
            <height>600</height>
            <format>R8G8B8</format>
          </image>
          <clip>
            <near>0.02</near>
            <far>300</far>
          </clip>
          <noise>
            <type>gaussian</type>
            <mean>0</mean>
            <stddev>0.007</stddev>
          </noise>
        </camera>
        <plugin name='realsense_camera_controller' filename='libgazebo_ros_camera.so'>
          <alwaysOn>1</alwaysOn>
          <updateRate>30.0</updateRate>
          <cameraName>realsense/camera</cameraName>
          <imageTopicName>realsense/image_raw</imageTopicName>
          <cameraInfoTopicName>realsense_camera_info</cameraInfoTopicName>
          <frameName>realsense_camera_link</frameName>
          <hackBaseline>0.07</hackBaseline>
          <distortionK1>0.0</distortionK1>
          <distortionK2>0.0</distortionK2>
          <distortionK3>0.0</distortionK3>
          <distortionT1>0.0</distortionT1>
          <distortionT2>0.0</distortionT2>
        </plugin>
        <pose>0.2 0.0175 0.6625 0 -0 0</pose>
      </sensor>
      <sensor name='intel_realsense_r200_depth' type='depth'>
        <always_on>1</always_on>
        <update_rate>30</update_rate>
        <camera name='realsense_depth_camera'>
          <horizontal_fov>1.39626</horizontal_fov>
          <image>
            <width>320</width>
            <height>240</height>
          </image>
          <clip>
            <near>0.1</near>
            <far>100</far>
          </clip>
        </camera>
        <plugin name='intel_realsense_r200_depth_driver' filename='libgazebo_ros_camera.so'>
          <ros/>
          <camera_name>intel_realsense_r200_depth</camera_name>
          <frame_name>realsense_camera_depth_optical_frame</frame_name>
          <hack_baseline>0.07</hack_baseline>
          <min_depth>0.001</min_depth>
        </plugin>
        <pose>0.2 0.0175 0.6625 0 -0 0</pose>
      </sensor>
    </link>
    <joint name='back_cl_j' type='revolute'>
      <pose relative_to='base_footprint'>-0.4 0.65 0.18 0 -0 0</pose>
      <parent>base_footprint</parent>
      <child>back_c_l</child>
      <axis>
        <xyz>0 0 1</xyz>
        <limit>
          <effort>10000</effort>
          <velocity>1000</velocity>
          <lower>-1e+16</lower>
          <upper>1e+16</upper>
        </limit>
        <dynamics>
          <spring_reference>0</spring_reference>
          <spring_stiffness>0</spring_stiffness>
        </dynamics>
      </axis>
    </joint>
    <link name='back_c_l'>
      <pose relative_to='back_cl_j'>0 0 0 0 -0 0</pose>
      <inertial>
        <pose>0.040802 -2e-06 -0.075306 0 -0 0</pose>
        <mass>3</mass>
        <inertia>
          <ixx>0.011943</ixx>
          <ixy>1.51346e-07</ixy>
          <ixz>0.00470867</ixz>
          <iyy>0.0127196</iyy>
          <iyz>-3.20566e-07</iyz>
          <izz>0.00449043</izz>
        </inertia>
      </inertial>
      <collision name='back_c_l_collision'>
        <pose>0 0 0 0 -0 0</pose>
        <geometry>
          <box>
            <size>0.01 0.01 0.01</size>
          </box>
        </geometry>
      </collision>
      <visual name='back_c_l_visual'>
        <pose>0 0 0 0 -0 0</pose>
        <geometry>
          <box>
            <size>0.01 0.01 0.01</size>
          </box>
        </geometry>
      </visual>
    </link>
    <joint name='back_wl_j' type='revolute'>
      <pose relative_to='back_c_l'>0.079407 0 0 1.57 -0 0</pose>
      <parent>back_c_l</parent>
      <child>back_w_l</child>
      <axis>
        <xyz>0 0 1</xyz>
        <limit>
          <lower>-1e+16</lower>
          <upper>1e+16</upper>
        </limit>
        <dynamics>
          <spring_reference>0</spring_reference>
          <spring_stiffness>0</spring_stiffness>
        </dynamics>
      </axis>
    </joint>
    <link name='back_w_l'>
      <pose relative_to='back_wl_j'>0 0 0 0 -0 0</pose>
      <inertial>
        <pose>-0.000406 -6.8e-05 1.5e-05 0 -0 0</pose>
        <mass>0.630033</mass>
        <inertia>
          <ixx>0.00669221</ixx>
          <ixy>1.46876e-06</ixy>
          <ixz>-1.83677e-07</ixz>
          <iyy>0.00381017</iyy>
          <iyz>2.02229e-07</iyz>
          <izz>0.00380711</izz>
        </inertia>
      </inertial>
      <collision name='back_w_l_collision'>
        <pose>0 0 0 0 -0 0</pose>
        <geometry>
          <cylinder>
            <length>0.078</length>
            <radius>0.13</radius>
          </cylinder>
        </geometry>
        <surface>
          <contact>
            <ode/>
          </contact>
          <friction>
            <ode/>
          </friction>
        </surface>
      </collision>
      <visual name='back_w_l_visual'>
        <pose>0 0 0 0 -0 0</pose>
        <geometry>
          <cylinder>
            <length>0.078</length>
            <radius>0.13</radius>
          </cylinder>
        </geometry>
        <material>
          <script>
            <name>Gazebo/Black</name>
            <uri>file://media/materials/scripts/gazebo.material</uri>
          </script>
        </material>
      </visual>
    </link>
    <joint name='back_cr_j' type='revolute'>
      <pose relative_to='base_footprint'>-0.4 -0.65 0.18 0 -0 0</pose>
      <parent>base_footprint</parent>
      <child>back_c_r</child>
      <axis>
        <xyz>0 0 1</xyz>
        <limit>
          <effort>10000</effort>
          <velocity>1000</velocity>
          <lower>-1e+16</lower>
          <upper>1e+16</upper>
        </limit>
        <dynamics>
          <spring_reference>0</spring_reference>
          <spring_stiffness>0</spring_stiffness>
        </dynamics>
      </axis>
    </joint>
    <link name='back_c_r'>
      <pose relative_to='back_cr_j'>0 0 0 0 -0 0</pose>
      <inertial>
        <pose>-0.040802 2e-06 -0.075306 0 -0 0</pose>
        <mass>3</mass>
        <inertia>
          <ixx>0.011943</ixx>
          <ixy>1.51329e-07</ixy>
          <ixz>-0.00470867</ixz>
          <iyy>0.0127196</iyy>
          <iyz>3.20627e-07</iyz>
          <izz>0.00449043</izz>
        </inertia>
      </inertial>
      <collision name='back_c_r_collision'>
        <pose>0 0 0 0 -0 0</pose>
        <geometry>
          <box>
            <size>0.01 0.01 0.01</size>
          </box>
        </geometry>
      </collision>
      <visual name='back_c_r_visual'>
        <pose>0 0 0 0 -0 0</pose>
        <geometry>
          <box>
            <size>0.01 0.01 0.01</size>
          </box>
        </geometry>
      </visual>
    </link>
    <joint name='back_wr_j' type='revolute'>
      <pose relative_to='back_c_r'>-0.079407 0 0 1.57 -0 0</pose>
      <parent>back_c_r</parent>
      <child>back_w_r</child>
      <axis>
        <xyz>0 0 1</xyz>
        <limit>
          <lower>-1e+16</lower>
          <upper>1e+16</upper>
        </limit>
        <dynamics>
          <spring_reference>0</spring_reference>
          <spring_stiffness>0</spring_stiffness>
        </dynamics>
      </axis>
    </joint>
    <link name='back_w_r'>
      <pose relative_to='back_wr_j'>0 0 0 0 -0 0</pose>
      <inertial>
        <pose>-0.000406 -6.8e-05 1.5e-05 0 -0 0</pose>
        <mass>0.630033</mass>
        <inertia>
          <ixx>0.00669221</ixx>
          <ixy>1.46876e-06</ixy>
          <ixz>-1.83677e-07</ixz>
          <iyy>0.00381017</iyy>
          <iyz>2.02229e-07</iyz>
          <izz>0.00380711</izz>
        </inertia>
      </inertial>
      <collision name='back_w_r_collision'>
        <pose>0 0 0 0 -0 0</pose>
        <geometry>
          <cylinder>
            <length>0.078</length>
            <radius>0.13</radius>
          </cylinder>
        </geometry>
        <surface>
          <contact>
            <ode/>
          </contact>
          <friction>
            <ode/>
          </friction>
        </surface>
      </collision>
      <visual name='back_w_r_visual'>
        <pose>0 0 0 0 -0 0</pose>
        <geometry>
          <cylinder>
            <length>0.078</length>
            <radius>0.13</radius>
          </cylinder>
        </geometry>
        <material>
          <script>
            <name>Gazebo/Black</name>
            <uri>file://media/materials/scripts/gazebo.material</uri>
          </script>
        </material>
      </visual>
    </link>
    <joint name='front_wl_j' type='revolute'>
      <pose relative_to='base_footprint'>0.4 0.65 0.26 1.57 -0 0</pose>
      <parent>base_footprint</parent>
      <child>front_w_l</child>
      <axis>
        <xyz>0 0 1</xyz>
        <limit>
          <lower>-1e+16</lower>
          <upper>1e+16</upper>
        </limit>
        <dynamics>
          <spring_reference>0</spring_reference>
          <spring_stiffness>0</spring_stiffness>
        </dynamics>
      </axis>
    </joint>
    <link name='front_w_l'>
      <pose relative_to='front_wl_j'>0 0 0 0 -0 0</pose>
      <inertial>
        <pose>0 0 0 0 -0 0</pose>
        <mass>3.63003</mass>
        <inertia>
          <ixx>0.00669221</ixx>
          <ixy>1.46876e-06</ixy>
          <ixz>-1.83677e-07</ixz>
          <iyy>0.00381017</iyy>
          <iyz>2.02229e-07</iyz>
          <izz>0.00380711</izz>
        </inertia>
      </inertial>
      <collision name='front_w_l_collision'>
        <pose>0 0 0 0 -0 0</pose>
        <geometry>
          <cylinder>
            <length>0.105</length>
            <radius>0.21</radius>
          </cylinder>
        </geometry>
        <surface>
          <contact>
            <ode/>
          </contact>
          <friction>
            <ode/>
          </friction>
        </surface>
      </collision>
      <visual name='front_w_l_visual'>
        <pose>0 0 0 0 -0 0</pose>
        <geometry>
          <cylinder>
            <length>0.105</length>
            <radius>0.21</radius>
          </cylinder>
        </geometry>
        <material>
          <script>
            <name>Gazebo/Black</name>
            <uri>file://media/materials/scripts/gazebo.material</uri>
          </script>
        </material>
      </visual>
    </link>
    <joint name='front_wr_j' type='revolute'>
      <pose relative_to='base_footprint'>0.4 -0.65 0.26 1.57 -0 0</pose>
      <parent>base_footprint</parent>
      <child>front_w_r</child>
      <axis>
        <xyz>0 0 1</xyz>
        <limit>
          <lower>-1e+16</lower>
          <upper>1e+16</upper>
        </limit>
        <dynamics>
          <spring_reference>0</spring_reference>
          <spring_stiffness>0</spring_stiffness>
        </dynamics>
      </axis>
    </joint>
    <link name='front_w_r'>
      <pose relative_to='front_wr_j'>0 0 0 0 -0 0</pose>
      <inertial>
        <pose>0 0 0 0 -0 0</pose>
        <mass>3.63003</mass>
        <inertia>
          <ixx>0.00669221</ixx>
          <ixy>1.46876e-06</ixy>
          <ixz>-1.83677e-07</ixz>
          <iyy>0.00381017</iyy>
          <iyz>2.02229e-07</iyz>
          <izz>0.00380711</izz>
        </inertia>
      </inertial>
      <collision name='front_w_r_collision'>
        <pose>0 0 0 0 -0 0</pose>
        <geometry>
          <cylinder>
            <length>0.105</length>
            <radius>0.21</radius>
          </cylinder>
        </geometry>
        <surface>
          <contact>
            <ode/>
          </contact>
          <friction>
            <ode/>
          </friction>
        </surface>
      </collision>
      <visual name='front_w_r_visual'>
        <pose>0 0 0 0 -0 0</pose>
        <geometry>
          <cylinder>
            <length>0.105</length>
            <radius>0.21</radius>
          </cylinder>
        </geometry>
        <material>
          <script>
            <name>Gazebo/Black</name>
            <uri>file://media/materials/scripts/gazebo.material</uri>
          </script>
        </material>
      </visual>
    </link>
    <plugin name='diff_drive' filename='libgazebo_ros_diff_drive.so'>
      <update_rate>30</update_rate>
      <left_joint>front_wl_j</left_joint>
      <right_joint>front_wr_j</right_joint>
      <wheel_separation>1.4</wheel_separation>
      <wheel_diameter>0.42</wheel_diameter>
      <max_wheel_torque>20</max_wheel_torque>
      <max_wheel_acceleration>1.0</max_wheel_acceleration>
      <command_topic>cmd_vel</command_topic>
      <publish_odom>1</publish_odom>
      <publish_odom_tf>1</publish_odom_tf>
      <publish_wheel_tf>0</publish_wheel_tf>
      <odometry_topic>odom</odometry_topic>
      <odometry_frame>odom</odometry_frame>
      <robot_base_frame>base_footprint</robot_base_frame>
    </plugin>
    <plugin name='turtlebot3_joint_state' filename='libgazebo_ros_joint_state_publisher.so'>
      <ros>
        <remapping>~/out:=joint_states</remapping>
      </ros>
      <update_rate>30</update_rate>
      <joint_name>front_wl_j</joint_name>
      <joint_name>front_wr_j</joint_name>
      <joint_name>back_wl_j</joint_name>
      <joint_name>back_wr_j</joint_name>
      <joint_name>back_cl_j</joint_name>
      <joint_name>back_cr_j</joint_name>
    </plugin>
    <frame name='back_left_joint' attached_to='base_link'>
      <pose>-0.4 0.65 0 0 -0 0</pose>
    </frame>
    <frame name='back_left' attached_to='back_left_joint'/>
    <frame name='back_right_joint' attached_to='base_link'>
      <pose>-0.4 -0.65 0 0 -0 0</pose>
    </frame>
    <frame name='back_right' attached_to='back_right_joint'/>
    <frame name='camera_rgb_optical_joint' attached_to='camera_rgb_frame'>
      <pose>0 0 0 -1.57 -0 -1.57</pose>
    </frame>
    <frame name='camera_rgb_optical_frame' attached_to='camera_rgb_optical_joint'/>
    <frame name='camera_rgb_joint' attached_to='camera_link'>
      <pose>0.003 0.011 0.009 0 -0 0</pose>
    </frame>
    <frame name='camera_rgb_frame' attached_to='camera_rgb_joint'/>
    <frame name='camera_joint' attached_to='base_link'>
      <pose>0.4 0 -0.25 0 -0 0</pose>
    </frame>
    <frame name='camera_link' attached_to='camera_joint'/>
    <frame name='front_left_joint' attached_to='base_link'>
      <pose>0.4 0.65 0 0 -0 0</pose>
    </frame>
    <frame name='front_left' attached_to='front_left_joint'/>
    <frame name='front_right_joint' attached_to='base_link'>
      <pose>0.4 -0.65 0 0 -0 0</pose>
    </frame>
    <frame name='front_right' attached_to='front_right_joint'/>
    <frame name='realsense_camera_color_optical_joint' attached_to='realsense_camera_color_frame'>
      <pose>0 0 0 -1.5708 -0 -1.5708</pose>
    </frame>
    <frame name='realsense_camera_color_optical_frame' attached_to='realsense_camera_color_optical_joint'/>
    <frame name='realsense_camera_color_joint' attached_to='realsense_camera_depth_frame'>
      <pose>0 0.015 0 0 -0 0</pose>
    </frame>
    <frame name='realsense_camera_color_frame' attached_to='realsense_camera_color_joint'/>
    <frame name='realsense_camera_depth_optical_joint' attached_to='realsense_camera_depth_frame'>
      <pose>0 0 0 -1.5708 -0 -1.5708</pose>
    </frame>
    <frame name='realsense_camera_depth_optical_frame' attached_to='realsense_camera_depth_optical_joint'/>
    <frame name='realsense_camera_left_ir_optical_joint' attached_to='realsense_camera_left_ir_frame'>
      <pose>0 0 0 -1.5708 -0 -1.5708</pose>
    </frame>
    <frame name='realsense_camera_left_ir_optical_frame' attached_to='realsense_camera_left_ir_optical_joint'/>
    <frame name='realsense_camera_left_ir_joint' attached_to='realsense_camera_depth_frame'>
      <pose>0 0 0 0 -0 0</pose>
    </frame>
    <frame name='realsense_camera_left_ir_frame' attached_to='realsense_camera_left_ir_joint'/>
    <frame name='realsense_camera_right_ir_optical_joint' attached_to='realsense_camera_right_ir_frame'>
      <pose>0 0 0 -1.5708 -0 -1.5708</pose>
    </frame>
    <frame name='realsense_camera_right_ir_optical_frame' attached_to='realsense_camera_right_ir_optical_joint'/>
    <frame name='realsense_camera_right_ir_joint' attached_to='realsense_camera_depth_frame'>
      <pose>0 -0.05 0 0 -0 0</pose>
    </frame>
    <frame name='realsense_camera_right_ir_frame' attached_to='realsense_camera_right_ir_joint'/>
    <frame name='realsense_camera_depth_joint' attached_to='realsense_camera_link'>
      <pose>0 0 0 0 -0 0</pose>
    </frame>
    <frame name='realsense_camera_depth_frame' attached_to='realsense_camera_depth_joint'/>
    <frame name='realsense_camera_link_joint' attached_to='realsense_camera_bottom_screw_frame'>
      <pose>0 0.0175 0.0125 0 -0 0</pose>
    </frame>
    <frame name='realsense_camera_link' attached_to='realsense_camera_link_joint'/>
    <frame name='realsense_camera_joint' attached_to='base_link'>
      <pose>0.2 0 -0.15 0 -0 0</pose>
    </frame>
    <frame name='realsense_camera_bottom_screw_frame' attached_to='realsense_camera_joint'/>
    <frame name='top_back_joint' attached_to='base_link'>
      <pose>-0.4 0 0.25 0 -0 0</pose>
    </frame>
    <frame name='top_back' attached_to='top_back_joint'/>
    <frame name='top_front_joint' attached_to='base_link'>
      <pose>0.4 0 0.25 0 -0 0</pose>
    </frame>
    <frame name='top_front' attached_to='top_front_joint'/>
    <frame name='top_left_joint' attached_to='base_link'>
      <pose>0 0.65 0.25 0 -0 0</pose>
    </frame>
    <frame name='top_left' attached_to='top_left_joint'/>
    <frame name='top_right_joint' attached_to='base_link'>
      <pose>0 -0.65 0.25 0 -0 0</pose>
    </frame>
    <frame name='top_right' attached_to='top_right_joint'/>
    <static>0</static>
    <frame name='base_joint' attached_to='base_footprint'>
      <pose>0 0 0.8 0 -0 0</pose>
    </frame>
    <frame name='base_link' attached_to='base_joint'/>
  </model>
</sdf>
